nohup: ignoring input
Traceback (most recent call last):
  File "/home/yunan.chen/.local/lib/python3.9/site-packages/urllib3/connectionpool.py", line 703, in urlopen
    httplib_response = self._make_request(
  File "/home/yunan.chen/.local/lib/python3.9/site-packages/urllib3/connectionpool.py", line 386, in _make_request
    self._validate_conn(conn)
  File "/home/yunan.chen/.local/lib/python3.9/site-packages/urllib3/connectionpool.py", line 1042, in _validate_conn
    conn.connect()
  File "/home/yunan.chen/.local/lib/python3.9/site-packages/urllib3/connection.py", line 414, in connect
    self.sock = ssl_wrap_socket(
  File "/home/yunan.chen/.local/lib/python3.9/site-packages/urllib3/util/ssl_.py", line 449, in ssl_wrap_socket
    ssl_sock = _ssl_wrap_socket_impl(
  File "/home/yunan.chen/.local/lib/python3.9/site-packages/urllib3/util/ssl_.py", line 493, in _ssl_wrap_socket_impl
    return ssl_context.wrap_socket(sock, server_hostname=server_hostname)
  File "/opt/miniconda2/lib/python3.9/ssl.py", line 500, in wrap_socket
    return self.sslsocket_class._create(
  File "/opt/miniconda2/lib/python3.9/ssl.py", line 1040, in _create
    self.do_handshake()
  File "/opt/miniconda2/lib/python3.9/ssl.py", line 1309, in do_handshake
    self._sslobj.do_handshake()
ConnectionResetError: [Errno 104] Connection reset by peer

During handling of the above exception, another exception occurred:

Traceback (most recent call last):
  File "/opt/miniconda2/lib/python3.9/site-packages/requests/adapters.py", line 439, in send
    resp = conn.urlopen(
  File "/home/yunan.chen/.local/lib/python3.9/site-packages/urllib3/connectionpool.py", line 787, in urlopen
    retries = retries.increment(
  File "/home/yunan.chen/.local/lib/python3.9/site-packages/urllib3/util/retry.py", line 550, in increment
    raise six.reraise(type(error), error, _stacktrace)
  File "/home/yunan.chen/.local/lib/python3.9/site-packages/urllib3/packages/six.py", line 769, in reraise
    raise value.with_traceback(tb)
  File "/home/yunan.chen/.local/lib/python3.9/site-packages/urllib3/connectionpool.py", line 703, in urlopen
    httplib_response = self._make_request(
  File "/home/yunan.chen/.local/lib/python3.9/site-packages/urllib3/connectionpool.py", line 386, in _make_request
    self._validate_conn(conn)
  File "/home/yunan.chen/.local/lib/python3.9/site-packages/urllib3/connectionpool.py", line 1042, in _validate_conn
    conn.connect()
  File "/home/yunan.chen/.local/lib/python3.9/site-packages/urllib3/connection.py", line 414, in connect
    self.sock = ssl_wrap_socket(
  File "/home/yunan.chen/.local/lib/python3.9/site-packages/urllib3/util/ssl_.py", line 449, in ssl_wrap_socket
    ssl_sock = _ssl_wrap_socket_impl(
  File "/home/yunan.chen/.local/lib/python3.9/site-packages/urllib3/util/ssl_.py", line 493, in _ssl_wrap_socket_impl
    return ssl_context.wrap_socket(sock, server_hostname=server_hostname)
  File "/opt/miniconda2/lib/python3.9/ssl.py", line 500, in wrap_socket
    return self.sslsocket_class._create(
  File "/opt/miniconda2/lib/python3.9/ssl.py", line 1040, in _create
    self.do_handshake()
  File "/opt/miniconda2/lib/python3.9/ssl.py", line 1309, in do_handshake
    self._sslobj.do_handshake()
urllib3.exceptions.ProtocolError: ('Connection aborted.', ConnectionResetError(104, 'Connection reset by peer'))

During handling of the above exception, another exception occurred:

Traceback (most recent call last):
  File "/home/yunan.chen/recall_lab/hk_book/rcmd-alg/pop_queue/routine_task/hk_book_six5/base_scripts/trans.py", line 393, in <module>
    ticketid = get_ticketid(s)
  File "/home/yunan.chen/recall_lab/hk_book/rcmd-alg/pop_queue/routine_task/hk_book_six5/base_scripts/trans.py", line 37, in get_ticketid
    r = s.get(NEW_TICKET_API)
  File "/opt/miniconda2/lib/python3.9/site-packages/requests/sessions.py", line 555, in get
    return self.request('GET', url, **kwargs)
  File "/opt/miniconda2/lib/python3.9/site-packages/requests/sessions.py", line 542, in request
    resp = self.send(prep, **send_kwargs)
  File "/opt/miniconda2/lib/python3.9/site-packages/requests/sessions.py", line 677, in send
    history = [resp for resp in gen]
  File "/opt/miniconda2/lib/python3.9/site-packages/requests/sessions.py", line 677, in <listcomp>
    history = [resp for resp in gen]
  File "/opt/miniconda2/lib/python3.9/site-packages/requests/sessions.py", line 237, in resolve_redirects
    resp = self.send(
  File "/opt/miniconda2/lib/python3.9/site-packages/requests/sessions.py", line 655, in send
    r = adapter.send(request, **kwargs)
  File "/opt/miniconda2/lib/python3.9/site-packages/requests/adapters.py", line 498, in send
    raise ConnectionError(err, request=request)
requests.exceptions.ConnectionError: ('Connection aborted.', ConnectionResetError(104, 'Connection reset by peer'))
